Workbook
Name competition_replies: #REF!
Name competition_replies: Bewerbungsformblatt!$J$3:$J$225
Name competition_replies: #REF!
Name competition_replies: #REF!

Sheet Teilnahmebedingungen
A2: Vergabe von Dienstleistungen nach der VgV
A3: =Bewerbungsformblatt!A1
A4: =Bewerbungsformblatt!A2
A7: Sehr geehrte Damen und Herren, wir bitten Sie, für die Bewerbung Folgendes zu beachten:
A9: I. Bewerbung/Teilnahmeantrag
A11: 1. Schlusstermin für den Eingang der Bewerbungsunterlagen auf der Vergabeplattform ist: 12.03.2026/10:00
A13: 2. Der ausgefüllte Bewerbungsbogen ist elektronisch auf der Vergabeplattform als PDF einzustellen. Anlagen sind fortlaufend zu nummerieren. Änderungen und Erweiterungen in den vorgegebenen Texten sind nicht zulässig.
A15: Alternativ zum Ausfüllen der Punkte 3 - 11 des Bewerberbogens ist die Abgabe einer entsprechend ausgefüllten Einheitlichen Europäischen Eigenerklärung (EEE) zulässig. Die EEE kann nur die Angaben in den Punkten 3 - 11 des Bewerbungsformblatt ersetzen und ist als Anlage dem Bewerberbogen beizulegen. Der Bewerberbogen ist in allen übrigen Teilen auszufüllen und zusammen mit der ausgefüllten EEE und den ggf. geforderten Unterlagen auf die Vergabeplattform (www.deutsche-evergabe.de) hochzuladen; die zur EEE gehörenden Unterlagen sind entweder ebenfalls als Anlage hochzuladen oder gem. § 50 Abs. 3 Nr. 1 VgV elektronisch abrufbar unter einer anzugebenden Web-Adresse (URL) zur Verfügung zu stellen.
A17: 3. Vorlage von Nachweisen, Angaben und Unterlagen:‎
A18: a. Bewerber haben zum Nachweis der Eignung mit der Bewerbung den ‎beigefügten Bewerbungsbogen vollständig ausgefüllt vorzulegen und die ‎entsprechenden geforderten Nachweise beizufügen.‎ Der Auftraggeber hat gem. § 56 (2) VgV festgelegt, dass keine Unterlagen nachgefordert werden. Die Nichtvorlage führt zum Ausschluss aus dem Wettbewerb. Die nach Prüfung der Teilnahmeanträge ausgewählten Bewerber werden voraussichtlich in der KW 13/ 2026 zur Abgabe eines Honorarangebots sowie Einreichung eines Konzepts aufgefordert. b. Die Bewerbererklärung ist von jedem Unternehmen (auch innerhalb einer ‎Bewerbergemeinschaft) und Subunternehmer/Nachunternehmer gesondert auszufüllen.‎
A20: 4. Zulässige Einzelbewerbung oder Bietergemeinschaft, an die der Auftrag vergeben ‎werden kann: Einzelbewerber oder Arbeitsgemeinschaft (ARGE), ‎gesamtschuldnerisch haftend mit bevollmächtigtem Vertreter. Mehrfachbewerbungen einzelner Mitglieder einer ARGE sind unzulässig und ‎führen zur Nichtberücksichtigung sämtlicher betroffener ‎Bewerbergemeinschaften im weiteren Verfahren (dies gilt auch für ‎Subunternehmer).‎
A22: 5. Die tatsächlichen Leistungserbringer (Personen) im Auftragsfall sind namentlich zu benennen und mit beruflicher Qualifikation anzugeben. Der Nachweis der fachlichen Qualifikation („Architekt") für den Inhaber, die Inhaberin oder mindestens einer Führungskraft des Unternehmens ist durch Nachweis der Eintragung in das Berufsregister bzw. nach Art. 2 Bau KaG und durch Angaben zur Berufserfahrung in Jahren zu führen. Juristische Personen müssen für die Durchführung der Aufgabe einen verantwortlichen Berufsangehörigen benennen. Zudem hat der Bewerber / die ARGE im Bewerbungsbogen die Beschäftigtenzahl des Unternehmens (bzgl. Architekten, Ingenieur und weiterer Mitarbeiter) anzugeben. Für die als Projektleiter/stv. Projktleiter vorgesehenen Personen ist der Nachweis für den Berufsabschluss in Fachrichtung Architektur (Dipl.-Ing. univ/TU/TH/FH, Bachelor, Master o. vglb.) zu erbringen. Für die für das konkrete Projekt für die Bauleitung vorgesehene verantwortliche Person ist der Nachweis für einen Berufsabschluss/Berufsbezeichnung als Ingenieur, Architekt, Meister, Techniker oder vergleichbar - jeweils Fachrichtung Bau - zu erbringen. Es ist ferner anzugeben, welche Teile des Auftrags das Unternehmen unter Umständen als ‎Unteraufträge zu vergeben beabsichtigt.‎
A24: 6. Die gelb hinterlegten Felder des Bewerbungsformblatts sind zwingend auszufüllen, die grau hinterlegten Felder bei Bedarf. Bewerbungen mit fehlenden Angaben bei Pflichtfeldern sowie fehlenden Nachweisen werden nicht berücksichtigt und führen in der Regel zum Ausschluss des Teilnahmeantrags. Änderungen, Abweichungen und Nichteinhaltungen sind zu kommentieren.
A26: 7. Im Rahmen des Teilnahmewettbewerbs wird die Fachkunde, Leistungsfähigkeit und Zuverlässigkeit gemäß VgV § 42 - 51 bewertet. Die im Einzelnen maßgebenden Kriterien und Wichtungen für die Wertung der Bewerbungen entnehmen Sie bitte beiliegendem Bewertungsschema. Die Auswahl der Teilnehmer erfolgt nach formaler Prüfung der Vollständigkeit der ‎in den Vergabeunterlagen geforderten Erklärungen und Nachweise, auf der ‎Grundlage des einheitlichen Bewertungsschemas. Die maximal mögliche Gesamtpunktzahl beträgt 405 Punkte. Die Bewerber (3 – 5) mit der höchsten Bewertung werden zur Verhandlung ‎aufgefordert. Bei Punktgleichheit und wenn keine weitere Differenzierung mehr ‎möglich ist, entscheidet das Los über die Teilnahme am weiteren ‎Verhandlungsverfahren.‎
A28: 8. Die Referenzangaben sind gemäß VgV § 46 (3) vorzulegen. Die Leistungsphase 8 muss abgeschlossen sein (Zeitraum 01.06.2019 - Veröffentlichungsdatum). Die Referenzen werden gemäß beigefügtem "Bewertungsschema Referenzen" bewertet und in der Gesamt-Auswertung berücksichtigt. Es sind 2 Referenzen vorzulegen (Formblatt "Büroreferenz" sowie ein Beiblatt mit detaillierter Projektbeschreibung gefordert). Es wird ein Mittelwert aus den einzelnen Referenz-Auswertungen gebildet. Das Gesamtpunkte-Ergebnis wird gemäß Bewertungsschema in die Gesamtauswertung übernommen (siehe Bewertungsschema Referenzen). Der Auftraggeber behält sich vor, bei den Bewerbern bzw. den Auftraggebern ‎Referenzauskünfte über die eingereichten Referenzen einzuholen. Bei ‎negativer Referenzauskunft wird dies im Rahmen der Bewertung ‎entsprechend berücksichtigt.
... A48: Die KUGLER Ingenieurbüro GmbH ist durch die Auslober zur Durchführung des Verfahrens beauftragt und erteilt sämtliche Auskünfte im Namen des Auftraggebers über die genannten Kontaktstellen. Die zum Vergabeverfahren gestellten Fragen werden neutralisiert, beantwortet und über die Vergabeplattform zur Verfügung gestellt.

Sheet Bewerbungsformblatt
A1: Verhandlungsverfahren - Mittagsbetreuung und Grundschulerweiterung Lenggries
A2: Leistungen der Objektplanung für Gebäude und Innenräume gem. §§ 33 ff HOAI - LPH 1 - 9
A4: Bewerber: | J4: Hansa Planungsgruppe GmbH
A6: 1 | B6: Bewerbung für | D6: =A2
A9: 2 | B9: Name des Büros / Unternehmens: | J9: Hansa Planungsgruppe GmbH
A11: 2.1 | B11: Straße, Hausnummer | J11: Hammerbrookstraße 74
B13: PLZ, Ort | J13: 20097 Hamburg
A15: 2.2 | B15: Telefon: | J15: +49 40 5487 2310
A17: 2.3 | B17: Fax:
A19: 2.4 | B19: E-Mail: | J19: vergabe@hansa-planungsgruppe.de
A21: 2.5 | B21: Ansprechpartner: | J21: Dipl.-Ing. Anna-Lena Krüger
A23: 2.6 | B23: Gründungsjahr des Büros:
A25: 2.7 | B25: Weitere Niederlassungen:
A27: 2.8 | B27: Eigenerklärung Bezug Russland (Hierzu ist das ausgefüllte Beiblatt 'Eigenerklärung Bezug Russland' beizulegen): | I27: Anlage Nr.
A29: 2.9 | B29: Angaben zur Verwendung einer Einheitlichen Europäischen Eigenerklärung (EEE) (§50 VgV): Das Unternehmen hat eine Einheitliche Europäische Eigenerklärung (EEE) als vorläufigen Nachweis ausgefüllt und als Anlage hochgeladen. | J29: ja: nein: Falls "ja", bitte als Anlage zum Bewerberbogen hochladen. Falls eine bereits bei einer früheren Auftragsvergabe verwendete Einheitliche Europäische Eigenerklärung wiederverwendet wird, muss das Unternehmen bestätigen, dass die darin enthaltenen Informationen weiterhin zutreffend sind.
I31: Anlage Nr.
A34: 3 | B34: Zertifikate
A36: 3.1 | B36: Zertifikate des Unternehmens
A38: a) | B38: Eintragung Inhaber/Führungskraft in das Berufsregister | I38: Anlage Nr.
A40: b) | B40: Studiennachweise und Bescheinigungen der beruflichen Befähigung
B41: Inhaber/Führungskraft | I41: Anlage Nr.
A43: 3.2 | B43: Ist das Unternehmen in den einschlägigen Berufs- oder Handelsregistern seines Niederlassungsmitgliedstaates eingetragen? | J43: ja
J44: Falls "ja", ist ein aktueller Auszug (nicht älter als 6 Monate) in Kopie beizufügen
I46: Anlage Nr.
A49: 4 | B49: Liegt eine Arbeitsgemeinschaft vor? | J49: nein
E50: Falls "ja" Angabe des vertretungsberechtigten Büro
A52: 4.1 | B52: Angabe zum Leistungsanteil des unter Nr. 2 genannten Büros bei Arbeitsgemeinschaften (Leistungen nach HOAI):
A55: 4.2 | B55: Bei Arbeitsgemeinschaften sind die Formulare je ARGE-Partner getrennt auszufüllen.
B56: Es ist jedoch gesamt je nur ein Projektleiter (9.1) bzw. stellv. Projektleiter (9.2) zu benennen.
A58: 4.3 | B58: Bei Arbeitsgemeinschaften ist eine entsprechende Erklärung der gesamtschuldnerischen Haftung mit Benennung des Ansprechpartners vorzulegen.
I59: Anlage Nr.
A62: 5 | B62: Liegt eine Unterbeauftragung vor? | J62: ja
A64: 5.1 | B64: Bei Auftragsanteil im Unterauftrag sind die Formulare gemäß § 44 VgV
B65: je Nachunternehmer auszufüllen (nur Nummern 2, 3, 6, 10, ggf. 9).
A67: 5.2 | B67: Art / Umfang der Unterbeauftragung (Leistungen nach HOAI):
A71: 5.3 | B71: Bei einer Unterbeauftragung ist eine Verpflichtungserklärung des
B72: Nachunternehmers vorzulegen, im Auftragsfall die für den Hauptunternehmer
B73: zur Auftragserfüllung erforderlichen Leistungen zu erbringen.
I74: Anlage Nr.
A77: 6 | B77: Nachweis der fachlichen Eignung gem. § 46 (3) 8 VgV
...

Sheet  Erklärung
C5: =Bewerbungsformblatt!A1
C7: =Bewerbungsformblatt!A2
C10: Erklärung zur freiberuflichen und unabhängigen Tätigkeit sowie der Richtigkeit der Angaben.
C12: 1 | D12: Ich/wir erkläre/n, dass das Unternehmen freiberuflich und unabhängig tätig ist.
D13: Es besteht keine Verknüpfung zu Gewerbebetrieben (VgV § 42).
C15: 2 | D15: Liegen Ausschlusskriterien nach VgV §§ 42, 48 sowie GWB §§ 123, 124 vor?
D17: Ja: | G17: Nein: X
D18: Falls ja, ist als Anlage eine gesonderte Erklärung in Textform abzugeben, die alle erforderlichen Angaben zum Sachverhalt und zu einer eventuellen Selbstreinigung nach § 125 GWB enthält.
C20: 3 | D20: Sind Sie als Bewerber bzw. ist ein nach Satzung oder Gesetz für den Bewerber Vertretungsberechtigter in den letzten zwei Jahren
D21: • gem. § 21 Abs. 1 Satz 1 oder 2 Schwarzarbeitsbekämpfungsgesetz oder
D22: • gem. § 21 Abs. 1 Arbeitnehmerentsendegesetz oder
D23: • gem. § 19 Abs. 1 Mindestlohngesetz mit einer Freiheitsstrafe von mehr als drei Monaten oder einer Geldstrafe von mehr als 90 Tagessätzen oder einer Geldbuße von mehr als 2.500 Euro belegt worden?
D25: Ja: | G25: Nein: X
D26: Falls ja, ist eine Erklärung in Textform abzugeben, die alle erforderlichen Angaben zum Sachverhalt enthält sowie etwaige Maßnahmen zur Verhinderung weiterer Verstöße beschreibt.
C28: 4 | D28: Ich/wir versicher/n, die übermittelten Unterlagen/Informationen/Angaben vertraulich zu
D29: behandeln VgV § 5.
C31: 5 | D31: Ich/wir versichern/n hiermit die Richtigkeit aller Angaben auf den Formularen, Nachweise und Anlagen.
D35: Hamburg | J35: Hansa Planungsgruppe GmbH, Dipl.-Ing. Anna-Lena Krüger
D36: Ort, Datum | I36: Stempel, Name (Textform zugelassen)

Sheet Eigenerklärung Bezug Russland
C3: =Bewerbungsformblatt!A1
C5: =Bewerbungsformblatt!A2
C8: Eigenerklärung Bezug Russland | J8: 127 / L 127 / III.27
J9: (Erklärung Bezug Russland)
C11: Entsprechend der Verordnung (EU) 2022/576 dürfen öffentliche Aufträge und Konzessionen nach dem 9. April 2022 nicht an Personen oder Unternehmen vergeben werden, die einen Bezug zu Russland im Sinne der Vorschrift aufweisen. Dies um- fasst sowohl unmittelbar als Bewerber, Bieter oder Auftragnehmer auftretende Personen oder Unternehmen als auch mittel- bar, mit mehr als zehn Prozent, gemessen am Auftragswert, beteiligte Unterauftragnehmer, Lieferanten oder Eignungs- verleiher.
C13: Ein Bezug zu Russland im Sinne der Vorschrift besteht
C14: a) durch die russische Staatsangehörigkeit des Bewerbers/Bieters oder die Niederlassung des Bewerbers/Bieters in Russland,
C15: b) durch die Beteiligung einer natürlichen Person oder eines Unternehmens, auf die eines der Kriterien nach Buchstabe a zutrifft, am Bewerber/Bieter über das Halten von Anteilen im Umfang von mehr als 50 Prozent,
C16: c) durch das Handeln der Bewerber/Bieter im Namen oder auf Anweisung von Personen oder Unternehmen, auf die die Kriterien der Buchstaben a) und/oder b) zutreffen.
C17: Bereits vor dem 9. April 2022 geschlossene Verträge mit solchen Personen oder Unternehmen mit Bezug zu Russland dürfen nur bis zum 10. Oktober 2022 fortgeführt werden.
C19: Maßnahmennummer: | E19: 107-01
H22: Hansa Planungsgruppe GmbH, Hammerbrookstraße 74, 20097 Hamburg, USt-IdNr.: DE318742591
H26: (Name, Anschrift und Ust.-ID-Nr. des Unternehmens - Textform zugelassen)
C28: Ich/ Wir erkläre(n), dass für mein/ unser Unternehmen keiner der in den Buchstaben a) bis c) genannten Fälle zutrifft.
C29: Ich/ Wir erkläre(n), dass ich/ wir zur Ausführung des Auftrags für Teile der Leistung
I71: Dipl.-Ing. Anna-Lena Krüger
C72: Ort, Datum | H72: Stempel, Name (Textform zugelassen)

Sheet Wertung Teilnahmewettbewerb
B2: =Bewerbungsformblatt!A1
B3: =Bewerbungsformblatt!A2
B5: Bewertungsschema | E5: max. Punktzahl | F5: Wichtung | G5: Gesamtpunkte
B7: Allgemein: | C7: Formulare, bei denen Pflichtfelder oder Beiblätter unvollständig ausgefüllt sind. | E7: Nichtberücksichtigung des Teilnahmeantrags
B9: Zu 2.8) | C9: Eigenerklärung Bezug auf Russland
C10: Bei Nichtvorlage Eigenerklärung Bezug auf Russland | E10: Nichtberücksichtigung des Teilnahmeantrags
B12: Zu 2.9) | C12: Einheitliche Europäische Eigenerklärung (EEE) | E12: optional - siehe Teilnahmebedigungen
B14: zu 3.1) | C14: Fehlende Zertifikate des Unternehmens
C15: a) Eintragung Inhaber/Führungskraft in Liste der Architekten-/Ingenieurkammer | E15: Nichtberücksichtigung des Teilnahmeantrags
C16: b) Studiennachweise und Bescheinigungen der beruflichen Befähigung Inhaber/Führungskräft | E16: Nichtberücksichtigung des Teilnahmeantrags
B18: zu 3.2) | C18: Fehlende Eintragung in einschlägige Berufs- oder Handelsregister (sofern einschlägig) | E18: Nichtberücksichtigung des Teilnahmeantrags
B20: zu 4.3) | C20: Fehlende Anlagen bei ARGE | E20: Nichtberücksichtigung des Teilnahmeantrags
C21: Bei einer ARGE erfolgt eine zusammengefasste Wertung der Punkte
C22: 6, 7, 8, 11
B24: zu 5) | C24: Fehlende Anlage bei Unterbeauftragung | E24: Nichtberücksichtigung des Teilnahmeantrags
B26: zu 6.1) | C26: Architekten (Dipl.-Ing. univ/TU/TH/FH, Master, Bachelor o. vglb.)
C27: ≥ 4 | D27: = 3 Pkt. | E27: 3 | F27: 15 | G27: =E27*F27
C28: = 3 | D28: = 2 Pkt.
C29: ≤ 2 | D29: = 1 Pkt
B31: zu 6.2) | C31: Mitarbeiter, die mit der Bauleitung betraut sind
C32: ≥ 2 | D32: = 2 Pkt. | E32: 2 | F32: 15 | G32: =E32*F32
C33: = 1 | D33: = 1 Pkt
C35: Bei Nichtvorlage Organigramm | E35: keine Angaben -> Nichtberücksichtigung des Teilnahmeantrags
B37: zu 7) | C37: Nachweis der fachlichen Eignung
B39: zu 7.1) | C39: Rechnerarbeitsplätze
C40: ≥ 5 | D40: = 3 Pkt. | E40: 3 | F40: 5 | G40: =(E40+E45+E49+E53+E57)*F40
C41: ≥ 3 | D41: = 2 Pkt.
C42: ≤ 2 | D42: = 1 Pkt.
B44: zu 7.2) | C44: Ausschreibungsprogramm (z. B. Bechmann, Orca)
C45: vorhanden | D45: = 1 Pkt. | E45: 1
C46: nicht vorhanden | D46: = 0 Pkt.
B48: zu 7.3) | C48: MS Projekt oder kompatibles Programm
C49: vorhanden | D49: = 1 Pkt. | E49: 1
C50: nicht vorhanden | D50: = 0 Pkt.
B52: zu 7.4) | C52: Kostensteuerungsprogramm
C53: vorhanden | D53: = 1 Pkt. | E53: 1
C54: nicht vorhanden | D54: = 0 Pkt.
B56: zu 7.5) | C56: CAD
C57: vorhanden | D57: = 1 Pkt. | E57: 1
C58: nicht vorhanden | D58: = 0 Pkt.
...

Sheet Büroreferenz 1
A2: =Bewerbungsformblatt!A1
A4: =Bewerbungsformblatt!A2
A6: Büro: | C6: Hansa Planungsgruppe GmbH
A7: Referenz-Nummer: | C7: 1
A9: Mindestkriterium / Wertungs- kriterium Nummer | B9: Referenzprojekt: | C9: jede Zeile ist auszufüllen - bei fehlenden Angaben oder nicht eindeutigen Angaben -> keine Wertung der Referenz Die Mindestkriterien sind zwingend zu erfüllen -> ansonsten keine Wertung der Referenz
A11: - | B11: Bezeichnung des Projekts (Benennung des BH einschl. Kontaktdaten) | C11: Energetische Sanierung und Erweiterung Schulcampus Nord, Freie und Hansestadt Hamburg, SBH | Schulbau Hamburg, An der Stadthausbrücke 1, 20355 Hamburg
A12: Mindestkriterium 1 | B12: ='Bewertungsschema Referenzen'!B8 | C12: August 2023
A13: Mindestkriterium 2 | B13: ='Bewertungsschema Referenzen'!B9 | C13: Ja, Honorarzone Objektplanung: III
A14: Wettbewerbs- kriterium 1 | B14: ='Bewertungsschema Referenzen'!B10 | C14: 8
A15: Wettbewerbs- kriterium 2 | B15: ='Bewertungsschema Referenzen'!B11 | C15: ja | E15: Secondary school campus
A16: Wettbewerbs- kriterium 3 | B16: ='Bewertungsschema Referenzen'!B12 | C16: ja | E16: Construction was executed in phases during ongoing school operations.
A17: Wettbewerbs- kriterium 4 | B17: ='Bewertungsschema Referenzen'!B13 | C17: ja | E17: Erweiterung Schulcampus Nord (partial new construction)
A18: Wettbewerbs- kriterium 5 | B18: ='Bewertungsschema Referenzen'!B14 | C18: 14730000
A19: Wettbewerbs- kriterium 6 | B19: ='Bewertungsschema Referenzen'!B15 | C19: ja | E19: Freie und Hansestadt Hamburg, SBH | Schulbau Hamburg
A20: Wettbewerbs- kriterium 7 | B20: ='Bewertungsschema Referenzen'!B16 | C20: nein | E20: ja -> Beschreibung:

Sheet Büroreferenz 2
A2: =Bewerbungsformblatt!A1
A4: =Bewerbungsformblatt!A2
A6: Büro: | C6: Hansa Planungsgruppe GmbH
A7: Referenz-Nummer: | C7: 2
A9: Mindestkriterium / Wertungs- kriterium Nummer | B9: Referenzprojekt: | C9: jede Zeile ist auszufüllen - bei fehlenden Angaben oder nicht eindeutigen Angaben -> keine Wertung der Referenz Die Mindestkriterien sind zwingend zu erfüllen -> ansonsten keine Wertung der Referenz
A11: - | B11: Bezeichnung des Projekts (Benennung des BH einschl. Kontaktdaten) | C11: Studentenwohnheim Altona - Modernisierung und Dachaufstockung, Bauherr: Studierendenwerk Hamburg AöR, Grindelallee 9, 20146 Hamburg
A12: Mindest- kriterium 1 | B12: ='Bewertungsschema Referenzen'!B8 | C12: Juli 2021
A13: Mindest- kriterium 2 | B13: ='Bewertungsschema Referenzen'!B9 | C13: Honorarzone III
A14: Wettbewerbs- kriterium 1 | B14: ='Bewertungsschema Referenzen'!B10 | C14: 8
A15: Wettbewerbs- kriterium 2 | B15: ='Bewertungsschema Referenzen'!B11 | C15: nein | E15: ja -> Beschreibung:
A16: Wettbewerbs- kriterium 3 | B16: ='Bewertungsschema Referenzen'!B12 | C16: ja | E16: Teilweise, nach Bauabschnitten
A17: Wettbewerbs- kriterium 4 | B17: ='Bewertungsschema Referenzen'!B13 | C17: ja | E17: Dachaufstockung
A18: Wettbewerbs- kriterium 5 | B18: ='Bewertungsschema Referenzen'!B14 | C18: 8.410.000
A19: Wettbewerbs- kriterium 6 | B19: ='Bewertungsschema Referenzen'!B15 | C19: ja | E19: Studierendenwerk Hamburg AöR
A20: Wettbewerbs- kriterium 7 | B20: ='Bewertungsschema Referenzen'!B16 | C20: ja/nein | E20: ja -> Beschreibung:

Sheet Büroreferenz ff
A2: =Bewerbungsformblatt!A1
A4: =Bewerbungsformblatt!A2
A6: Büro: | C6: Hansa Planungsgruppe GmbH
A7: Referenz-Nummer: | C7: 2
A9: Mindestkriterium / Wertungs- kriterium Nummer | B9: Referenzprojekt: | C9: jede Zeile ist auszufüllen - bei fehlenden Angaben oder nicht eindeutigen Angaben -> keine Wertung der Referenz Die Mindestkriterien sind zwingend zu erfüllen -> ansonsten keine Wertung der Referenz
A11: - | B11: Bezeichnung des Projekts (Benennung des BH einschl. Kontaktdaten) | C11: Modernisierung Wohnanlage Elbterrassen, Elbwohnungsbau Hamburg GmbH, Überseering 12, 22297 Hamburg
A12: Mindest- kriterium 1 | B12: ='Bewertungsschema Referenzen'!B8 | C12: November 2022
A13: Mindest- kriterium 2 | B13: ='Bewertungsschema Referenzen'!B9 | C13: Ja, Honorarzone III
A14: Wettbewerbs- kriterium 1 | B14: ='Bewertungsschema Referenzen'!B10 | C14: 8
A15: Wettbewerbs- kriterium 2 | B15: ='Bewertungsschema Referenzen'!B11 | C15: nein | E15: ja -> Beschreibung:
A16: Wettbewerbs- kriterium 3 | B16: ='Bewertungsschema Referenzen'!B12 | C16: ja | E16: Phased works in occupied building with temporary supply arrangements
A17: Wettbewerbs- kriterium 4 | B17: ='Bewertungsschema Referenzen'!B13 | C17: nein | E17: ja -> Beschreibung:
A18: Wettbewerbs- kriterium 5 | B18: ='Bewertungsschema Referenzen'!B14 | C18: 11.680.000
A19: Wettbewerbs- kriterium 6 | B19: ='Bewertungsschema Referenzen'!B15 | C19: nein | E19: ja -> Beschreibung:
A20: Wettbewerbs- kriterium 7 | B20: ='Bewertungsschema Referenzen'!B16 | C20: ja/nein | E20: ja -> Beschreibung:

Sheet Bewertungsschema Referenzen
A1: =Bewerbungsformblatt!A1
A2: =Bewerbungsformblatt!A2
A4: Punkteschema
A6: Punkte | C6: 5 | D6: 4 | E6: 3 | F6: 2 | G6: 1 | H6: 0
C7: Bei fehlenden Angaben oder nicht eindeutigen Angaben -> keine Wertung der Referenz! Sind Mindestkriterien nicht erfüllt -> keine Wertung der Referenz!
A8: Mindest- kriterium 1 | B8: Abschluss LPH 8 (01.06.2019- Veröffentlichungsdatum 04.02.26) | C8: ü | D8: - | E8: - | F8: - | G8: - | H8: û keine Wertung
A9: Mindest- kriterium 2 | B9: Gebäude in der Honorarzone III | C9: ü | D9: - | E9: - | F9: - | G9: - | H9: û keine Wertung
A10: Wettbewerbs- kriterium 1 | B10: Anzahl erbrachter, zusammenhängender Leistungsphasen | C10: 8-9 Leistungsphasen | D10: 6-7 Leistungsphasen | E10: 4-5 Leistungsphasen | F10: 3-4 Leistungsphasen | G10: 1-2 Leistungsphasen | H10: û weniger oder keine Angabe
A11: Wettbewerbs- kriterium 2 | B11: Bildungsstätte (Grund- und weiterführende Schulen, wie Haupt-Mittelschule, Realschule, Gymnasium, oder vergleichbar) | C11: ü | D11: - | E11: - | F11: - | G11: - | H11: û weniger oder keine Angabe
A12: Wettbewerbs- kriterium 3 | B12: Bauarbeiten im laufenden Betrieb | C12: ü | D12: - | E12: - | F12: - | G12: - | H12: û oder keine Angabe
A13: Wettbewerbs- kriterium 4 | B13: Erweiterung an Bestand oder freistehender Neubau | C13: Erweiterung an Bestand | D13: - | E13: - | F13: - | G13: freistehender Neubau | H13: û oder keine Angabe
A14: Wettbewerbs- kriterium 5 | B14: Baukosten der KGR 300 - 400 im Sinne der DIN 276 (€ netto) | C14: ü >4,5 Mio € | D14: > 4,0 Mio € ≤ 4,5 Mio € | E14: > 3,5 Mio € ≤ 4,0 Mio € | F14: > 3,0 Mio € ≤ 3,5 Mio € | G14: > 2,5 Mio € ≤ 3,0 Mio € | H14: û weniger oder keine Angabe
A15: Wettbewerbs- kriterium 6 | B15: öffentlicher AG | C15: ü | D15: - | E15: - | F15: - | G15: - | H15: û oder keine Angabe
A16: Wettbewerbs- kriterium 7 | B16: geförderte Maßnahme | C16: ü | D16: - | E16: - | F16: - | G16: - | H16: û oder keine Angabe
A18: Punktevergabe | C18: 5 | D18: 4 | E18: 3 | F18: 2 | G18: 1 | H18: 0
A19: erreichte Punktzahl | C19: 45 ≥ 42 | D19: < 42 ≥ 38 | E19: < 38 ≥ 32 | F19: < 32 ≥ 28 | G19: < 28 ≥ 20 | H19: < 20

Sheet Wertung Zuschschlagskriterien
A1: =Bewerbungsformblatt!A1
A2: =Bewerbungsformblatt!A2
A5: Bewertungsbogen Konzept/Präsentation
A6: Die kursiv angegebenen Stichworte bei den Unterkriterien sind Beispielhaft und nur zur Orientierung für das Entscheidungsgremium gedacht und stellen keine definitive oder abschliessende Auflistung dar! Die Bewertung hat anhand der Inhalte der Präsentationen der einzelnen Büros zu erfolgen!
A10: 0. Kurzvorstellung des Büros
C11: Wertung | D11: Wichtung | E11: maximale Punktzahl
A12: 1. | B12: ANGABEN ZUR ARBEITSWEISE
C13: max. | E13: max.
A14: Bitte erläutern Sie anhand eines oder mehrerer geeigneter Referenzprojekte Ihre Herangehensweise an das Projekt unter folgenden Gesichtspunkten:
A15: a.) | B15: Im Auftragsfall werden die Leistungspflichten durch die dem Vertrag zu Grunde liegenden ZVB detailliert bestimmt. Bitte erläutern Sie, wie Sie die Erbringung der einzelnen Leistungen anbieten (Schilderung der Arbeitsweise bei der Abwicklung des Auftrags und Schwerpunkte Ihrer Tätigkeit). | C15: 5 | D15: 2 | E15: =C15*D15
A16: b.) | B16: Wie gestalten Sie Ihre Zusammenarbeit und Kommunikation mit den anderen Projektbeteiligten und dem Auftraggeber? | C16: 5 | D16: 2 | E16: =C16*D16
A17: c.) | B17: Welche Methoden zur Kosten- und Terminverfolgung haben Sie und wie gehen Sie bei Kosten- bzw. Terminabweichungen vor? | C17: 5 | D17: 4 | E17: =C17*D17
A18: d.) | B18: Umgang mit öffentlichen Projekten (AG), Vergabeverfahren (öffentliche/offene Verfahren), produktneutraler Ausschreibung, sowie dem Vergabehandbuch Bayern? | C18: 5 | D18: 3 | E18: =C18*D18
A19: 2. | B19: VERFÜGBARKEIT UND PERSONALEINSATZ
C20: max. | E20: max.
A21: a.) | B21: Wie werden Sie Ihre grundsätzliche Verfügbarkeit gewährleisten? Wie stellen Sie sich die Bauleitertätigkeit, insbesondere in Bezug auf die Verfügbarkeit, vor? | C21: 5 | D21: 5 | E21: =C21*D21
A22: b.) | B22: Welche Vertretungsregelungen im Urlaubs- und Krankheitsfall sehen Sie vor? | C22: 5 | D22: 3 | E22: =C22*D22
A23: c.) | B23: Der Auftraggeber möchte sicherstellen, dass durch das vorgesehene Personal eine zügige Durchführung des Projekts gewährleistet ist. Bitte zeigen sie auf, mit welchen personellen Mitteln Sie dies einhalten wollen. Erstellen Sie hierzu bitte einen Personaleinsatzplan inkl. den entsprechenden Vollzeitäquivalenten. | C23: 5 | D23: 7 | E23: =C23*D23
A24: 3. | B24: QUALIFIKATION DES ZUM EINSATZ KOMMENDEN PERSONALS
C25: max. | E25: max.
A26: Der Auftraggeber erwartet, dass der Projektleiter/ stellv. Projektleiter und Bauleiter, die zum Einsatz kommen, die entsprechende, einschlägige Berufserfahrung haben. Die Berufserfahrung soll persönlich anhand von Referenzprojekten dargestellt werden. ≥12 -jährige Berufserfahrung und 2 vergleichbare Referenzen erzielen volle Punktzahl (= 5 Pkt.) <12 -jährige Berufserfahrung ≥ 10 -jährige Berufserfahrung und 2 vergleichbare Referenzen erzielen 4 Pkt. <10 -jährige Berufserfahrung ≥ 6 -jährige Berufserfahrung und 2 vergleichbare Referenzen erzielen 3 Pkt. < 6 -jährige Berufserfahrung ≥ 4 -jährige Berufserfahrung und 2 vergleichbare Referenzen erzielen 2 Pkt. < 4 -jährige Berufserfahrung ≥ 1 -jährige Berufserfahrung und 2 vergleichbare Referenzen erzielen 1 Pkt.
A28: a.) | B28: Berufserfahrung des vorgesehenen Projektleiters | C28: 5 | D28: 5 | E28: =C28*D28
A29: b.) | B29: Berufserfahrung des stellvertretenden Projektleiters | C29: 5 | D29: 5 | E29: =C29*D29
A30: c.) | B30: Berufserfahrung des vorgesehenen Bauleiters | C30: 5 | D30: 5 | E30: =C30*D30
A31: 4. | B31: AUSEINANDERSETZUNG MIT DEM KONKRETEN VORHABEN
C32: max. | E32: max.
A33: Der Bieter soll zeigen, dass er sich gedanklich bereits ein erstes Mal mit dem Projekt auseinandergesetzt hat und zur Entwicklung praktikabler Lösungsansätze in der Lage ist. Hier kann der Bieter darlegen, wie eine Aufteilung der einzelnen Funktionsbereiche und Verkehrswege aussehen könnte. Ferner kann der Bieter erste gestalterische Überlegungen darlegen. Dies kann in Textform, gerne aber auch anhand von Grob-/Handskizzen erfolgen. Der Bieter soll ferner darlegen, wo die Herausforderungen des konkreten Projekts liegen. Der Auftraggeber erwartet hier ausdrücklich noch keinen vertieften Einstieg in die Planung.
A35: a.) | B35: Erstüberlegung zur Gestaltung | C35: 5 | D35: 8 | E35: =C35*D35
A36: b.) | B36: Erstüberlegung zur Aufteilung der Funktionsbereiche | C36: 5 | D36: 8 | E36: =C36*D36
A37: a.) | B37: Der Bieter hat darzulegen wie er sich die Umsetzung in Bezug auf Bauablauf und - Logistik vor dem Hintergrund vorstellt, dass die Maßnahme im laufenden Betrieb stattfindet. | C37: 5 | D37: 10 | E37: =C37*D37
A38: d.) | B38: Weitere Herausforderungen des konkreten Projekts. | C38: 5 | D38: 8 | E38: =C38*D38
A39: 5. | B39: Präsentation
C40: max. | E40: max.
A41: Im Rahmen der Präsentation der Konzeptschwerpunkte werden ferner folgende Aspekte gewertet:
A42: a.) | B42: Schwerpunktsetzung und Fachlichkeit der Präsentationsbeiträge von Projektleiter/ stellv. Projektleiter und vorgesehenem Bauleiter. | C42: 5 | D42: 2 | E42: =C42*D42
A43: b.) | B43: Zeitmanagement des Bieters im Rahmen der Präsentation | C43: 5 | D43: 2 | E43: =C43*D43
A44: c.) | B44: Antworten auf fachliche Nachfragen des Gremiums | C44: 5 | D44: 6 | E44: =C44*D44
A45: 6. | B45: HONORARPARAMETER
C46: max. | E46: max.
A47: Gesamthonorarangebot
...

Sheet Honorarangebot
B3: =Bewerbungsformblatt!A1
B4: =Bewerbungsformblatt!A2
B8: Honorarangebot
B11: Büro: | G11: Hansa Planungsgruppe GmbH
B13: Objekt | G13: Erweiterung Grundschule
B14: anrechenbare Kosten (netto) | G14: 5200000
B15: Honorarzone | G15: III
B16: Honorarsatz | G16: Basissatz
G17: Angabe in %
B18: Leistungsphasen und Bewertung HOAI | E18: 1 GE | F18: §§ 34, 35
E19: 2 VP
E20: 3 EP
E21: 4 GP
E22: 5 AP
E23: 6 VV
E24: 7 MV
E25: 8 OÜ
E26: 9 OB
B27: Gesamt: | G27: =SUM(G18:H26)
B29: Besondere Leistung:
B30: Bestandsaufnahme | H30: € netto
B31: Gewerkeweise Budgetierung und Aufteilung der Kostenberechnung der LPH3 | H31: € netto
B32: Erstellung Verwendungsnachweis | H32: € netto
B33: Überwachen der Mängelbeseitigung innerhalb der Verjährungsfrist (im Rahmen der Angebotslegung ist von 40 h auszugehen. Die Vergütung erfolgt aufwandsbezogen) | H33: € netto
B34: Teilnahme an öffentlichen Sitzungen bzw. sonstiger Gremien außerhalb der Bedarfsplaung (Preis für 1 Termin, Abrechnung erfolgt nach tatsächlicher Teilnahme) | H34: € netto
B35: Mithilfe bei der Fördermittelbeschaffung | H35: € netto
B36: Gesamt | G36: =SUM(G30:G35) | H36: € netto
B38: Umbau- und Modernisierungszuschlag § 6 Abs. 2 HOAI | H38: %
B40: Zeithonorar (1 Std.) | E40: Auftragnehmer*in/Inhaber*in | H40: € netto
E41: Ingenieur*in | H41: € netto
E42: sonstige Mitarbeiter*innen | H42: € netto
B43: Planungsnebenkosten | H43: %
B44: Bemerkungen (z. B. Nachlässe, Aufschläge, sonstiges)
B48: Ort, Datum, Unterschrift
